Workbook

Sheet Overview
A1: World Aviation Festival – Agenda
A3: Source | B3: https://hub.terrapinn.com/a0AN200000t9wgDMAQPA06066985/agenda
A4: Days included | B4: Day 2, Day 3
A5: Note | B5: Built from agenda text copied from the event hub. The site could not be fetched directly from this environment. Speaker job titles/organisations are split from 'Name, Title, Company' on the site; 'Additional speakers' are names hidden behind '+N more' on the site and are not listed here. Registration numbers are a snapshot at the time of copying.
A8: Sessions by stream
A9: Stream / Category | B9: Day 2 | C9: Day 3 | D9: Total
A10: AI / ML | B10: =COUNTIFS('All Sessions'!$E$2:$E$194,$A10,'All Sessions'!$B$2:$B$194,"Day 2") -> 8 | C10: =COUNTIFS('All Sessions'!$E$2:$E$194,$A10,'All Sessions'!$B$2:$B$194,"Day 3") -> 7 | D10: =SUM(B10:C10) -> 15
A11: Airline Keynote | B11: =COUNTIFS('All Sessions'!$E$2:$E$194,$A11,'All Sessions'!$B$2:$B$194,"Day 2") -> 16 | C11: =COUNTIFS('All Sessions'!$E$2:$E$194,$A11,'All Sessions'!$B$2:$B$194,"Day 3") -> 7 | D11: =SUM(B11:C11) -> 23
A12: Airport & Airline Collaboration | B12: =COUNTIFS('All Sessions'!$E$2:$E$194,$A12,'All Sessions'!$B$2:$B$194,"Day 2") -> 6 | C12: =COUNTIFS('All Sessions'!$E$2:$E$194,$A12,'All Sessions'!$B$2:$B$194,"Day 3") -> 5 | D12: =SUM(B12:C12) -> 11
A13: Airport - Operations | B13: =COUNTIFS('All Sessions'!$E$2:$E$194,$A13,'All Sessions'!$B$2:$B$194,"Day 2") -> 3 | C13: =COUNTIFS('All Sessions'!$E$2:$E$194,$A13,'All Sessions'!$B$2:$B$194,"Day 3") -> 2 | D13: =SUM(B13:C13) -> 5
A14: Airport - Traveller | B14: =COUNTIFS('All Sessions'!$E$2:$E$194,$A14,'All Sessions'!$B$2:$B$194,"Day 2") -> 5 | C14: =COUNTIFS('All Sessions'!$E$2:$E$194,$A14,'All Sessions'!$B$2:$B$194,"Day 3") -> 0 | D14: =SUM(B14:C14) -> 5
A15: Airport Keynote | B15: =COUNTIFS('All Sessions'!$E$2:$E$194,$A15,'All Sessions'!$B$2:$B$194,"Day 2") -> 6 | C15: =COUNTIFS('All Sessions'!$E$2:$E$194,$A15,'All Sessions'!$B$2:$B$194,"Day 3") -> 2 | D15: =SUM(B15:C15) -> 8
A16: Ancillaries | B16: =COUNTIFS('All Sessions'!$E$2:$E$194,$A16,'All Sessions'!$B$2:$B$194,"Day 2") -> 3 | C16: =COUNTIFS('All Sessions'!$E$2:$E$194,$A16,'All Sessions'!$B$2:$B$194,"Day 3") -> 0 | D16: =SUM(B16:C16) -> 3
A17: Customer Experience | B17: =COUNTIFS('All Sessions'!$E$2:$E$194,$A17,'All Sessions'!$B$2:$B$194,"Day 2") -> 8 | C17: =COUNTIFS('All Sessions'!$E$2:$E$194,$A17,'All Sessions'!$B$2:$B$194,"Day 3") -> 0 | D17: =SUM(B17:C17) -> 8
A18: Digital & IT | B18: =COUNTIFS('All Sessions'!$E$2:$E$194,$A18,'All Sessions'!$B$2:$B$194,"Day 2") -> 7 | C18: =COUNTIFS('All Sessions'!$E$2:$E$194,$A18,'All Sessions'!$B$2:$B$194,"Day 3") -> 5 | D18: =SUM(B18:C18) -> 12
A19: IROPS | B19: =COUNTIFS('All Sessions'!$E$2:$E$194,$A19,'All Sessions'!$B$2:$B$194,"Day 2") -> 3 | C19: =COUNTIFS('All Sessions'!$E$2:$E$194,$A19,'All Sessions'!$B$2:$B$194,"Day 3") -> 0 | D19: =SUM(B19:C19) -> 3
A20: Innovation | B20: =COUNTIFS('All Sessions'!$E$2:$E$194,$A20,'All Sessions'!$B$2:$B$194,"Day 2") -> 0 | C20: =COUNTIFS('All Sessions'!$E$2:$E$194,$A20,'All Sessions'!$B$2:$B$194,"Day 3") -> 1 | D20: =SUM(B20:C20) -> 1
A21: Loyalty | B21: =COUNTIFS('All Sessions'!$E$2:$E$194,$A21,'All Sessions'!$B$2:$B$194,"Day 2") -> 7 | C21: =COUNTIFS('All Sessions'!$E$2:$E$194,$A21,'All Sessions'!$B$2:$B$194,"Day 3") -> 6 | D21: =SUM(B21:C21) -> 13
... A28: Workshop | B28: =COUNTIFS('All Sessions'!$E$2:$E$194,$A28,'All Sessions'!$B$2:$B$194,"Day 2") -> 3 | C28: =COUNTIFS('All Sessions'!$E$2:$E$194,$A28,'All Sessions'!$B$2:$B$194,"Day 3") -> 1 | D28: =SUM(B28:C28) -> 4
A29: Total | B29: =SUM(B10:B28) -> 138 | C29: =SUM(C10:C28) -> 55 | D29: =SUM(D10:D28) -> 193

Sheet Day 2
A1: # | B1: Day | C1: Start | D1: End | E1: Stream / Category | F1: Format | G1: Session Title | H1: Speakers (Name – Job Title, Company) | I1: Speaker Names | J1: Organisations | K1: Speakers Listed | L1: Additional Speakers (not shown on site) | M1: Room / Stage | N1: Pavilion | O1: Room (as listed on site) | P1: Description / Discussion Points | Q1: Registered | R1: Capacity | S1: Places Left | T1: Registration Status
A2: 1 | B2: Day 2 | C2: 0.34375 | E2: Networking | F2: Networking | G2: Aviation Connect: Session 6 | H2: Host, World Aviation Festival | I2: Host | J2: World Aviation Festival | K2: 1 | M2: Aviation Connect Zone (Pavilion 2) | N2: Pavilion 2 | O2: Aviation Connect Zone Pavilion 2
A3: 2 | B3: Day 2 | C3: 0.38194444 | E3: Airline Keynote | F3: Welcome | G3: Official Welcome | H3: Carlos Oliveira – Chairman, Tap Air Portugal | I3: Carlos Oliveira | J3: Tap Air Portugal | K3: 1 | M3: Keynote Stage 1 (Pavilion 1) | N3: Pavilion 1 | O3: Keynote Theatre (Pavilion 1)
A4: 3 | B4: Day 2 | C4: 0.38541667 | E4: Airport Keynote | F4: Welcome | G4: Official Airport Partner Welcome | H4: Thierry Ligonnière – Chief Executive Officer, ANA Aeroportos de Portugal | I4: Thierry Ligonnière | J4: ANA Aeroportos de Portugal | K4: 1 | M4: Keynote Stage 2 (Pavilion 2) | N4: Pavilion 2 | O4: Keynote Stage 2 (Pavilion 2)
A5: 4 | B5: Day 2 | C5: 0.38888889 | E5: Airport Keynote | F5: Interview | G5: CEO Interview: Stefan Schulte, CEO, Fraport AG | H5: Stefan Schulte – Chief Executive Officer, Fraport AG Ben Thompson – Presenter, BBC | I5: Stefan Schulte, Ben Thompson | J5: Fraport AG, BBC | K5: 2 | M5: Keynote Stage 2 (Pavilion 2) | N5: Pavilion 2 | O5: Keynote Stage 2 (Pavilion 2)
A6: 5 | B6: Day 2 | C6: 0.38888889 | E6: Airline Keynote | F6: Interview | G6: CEO Interview: Luis Rodrigues, CEO, TAP Air Portugal | H6: Luís Rodrigues – Chief Executive Officer, Tap Air Portugal Peter Campbell – Global Transport Correspondent, Financial Times | I6: Luís Rodrigues, Peter Campbell | J6: Tap Air Portugal, Financial Times | K6: 2 | M6: Keynote Stage 1 (Pavilion 1) | N6: Pavilion 1 | O6: Keynote Stage 1 (Pavilion 1)
A7: 6 | B7: Day 2 | C7: 0.39583333 | E7: Airline Keynote | F7: Interview | G7: CEO Interview: Adrian Neuhauser, CEO, ABRA Group | H7: Adrian Neuhauser – Chief Executive Officer, Abra Group Peter Campbell – Global Transport Correspondent, Financial Times | I7: Adrian Neuhauser, Peter Campbell | J7: Abra Group, Financial Times | K7: 2 | M7: Keynote Stage 1 (Pavilion 1) | N7: Pavilion 1 | O7: Keynote Stage 1 (Pavilion 1)
A8: 7 | B8: Day 2 | C8: 0.39583333 | E8: Airport Keynote | F8: Interview | G8: CEO Interview: Thierry Ligonnière, CEO, ANA - Aeroportos de Portugal | H8: Thierry Ligonnière – Chief Executive Officer, ANA Aeroportos de Portugal Ben Thompson – Presenter, BBC | I8: Thierry Ligonnière, Ben Thompson | J8: ANA Aeroportos de Portugal, BBC | K8: 2 | M8: Keynote Stage 2 (Pavilion 2) | N8: Pavilion 2 | O8: Keynote Stage 2 (Pavilion 2)
A9: 8 | B9: Day 2 | C9: 0.40277778 | E9: Airport Keynote | F9: Interview | G9: CEO Interview: Pierre-Hugues Schmit, CEO, London Gatwick | H9: Pierre-Hugues Schmit – Chief Executive Officer, London Gatwick Airport Ben Thompson – Presenter, BBC | I9: Pierre-Hugues Schmit, Ben Thompson | J9: London Gatwick Airport, BBC | K9: 2 | M9: Keynote Stage 2 (Pavilion 2) | N9: Pavilion 2 | O9: Keynote Stage 2 (Pavilion 2)
A10: 9 | B10: Day 2 | C10: 0.40277778 | E10: Airline Keynote | F10: Interview | G10: CEO Interview: Roberto Alvo, CEO, LATAM | H10: Roberto Alvo – CEO, Latam Airlines Group Peter Campbell – Global Transport Correspondent, Financial Times | I10: Roberto Alvo, Peter Campbell | J10: Latam Airlines Group, Financial Times | K10: 2 | M10: Keynote Stage 1 (Pavilion 1) | N10: Pavilion 1 | O10: Keynote Stage 1 (Pavilion 1)
A11: 10 | B11: Day 2 | C11: 0.40972222 | E11: Airline Keynote | F11: Panel | G11: Keynote CEO Panel: Writing the next chapter of aviation history in an age of uncertainty | H11: Luís Rodrigues – Chief Executive Officer, Tap Air Portugal Adrian Neuhauser – Chief Executive Officer, Abra Group Roberto Alvo – CEO, Latam Airlines Group | I11: Luís Rodrigues, Adrian Neuhauser, Roberto Alvo | J11: Tap Air Portugal, Abra Group, Latam Airlines Group | K11: 3 | L11: 1 | M11: Keynote Stage 1 (Pavilion 1) | N11: Pavilion 1 | O11: Keynote Stage 1 (Pavilion 1) | P11: Investing in the right areas for growth: identifying true game changes from the trendy fad • Navigating geopolitical instability and preparing for unknowns to reduce the impact of disruption • Long Term Strategy planning by optimising operations and working with industry to solve supply chain constraint • Working as an industry to improve global challenges including sustainability, workforce challenges and safety
A12: 11 | B12: Day 2 | C12: 0.40972222 | E12: Airport Keynote | F12: Interview | G12: CEO Interview: Paul Griffiths, CEO, Dubai Airports | H12: Paul Griffiths – Chief Executive Officer, Dubai Airports Company Ben Thompson – Presenter, BBC | I12: Paul Griffiths, Ben Thompson | J12: Dubai Airports Company, BBC | K12: 2 | M12: Keynote Stage 2 (Pavilion 2) | N12: Pavilion 2 | O12: Keynote Stage 2 (Pavilion 2)
A13: 12 | B13: Day 2 | C13: 0.41666667 | E13: Airport Keynote | F13: Panel | G13: Keynote Panel: Growth without compromise – rethinking the airport model for sustainable growth | H13: Stefan Schulte – Chief Executive Officer, Fraport AG Warwick Brady – President & CEO, SWISSPORT Paul Griffiths – Chief Executive Officer, Dubai Airports Company | I13: Stefan Schulte, Warwick Brady, Paul Griffiths | J13: Fraport AG, SWISSPORT, Dubai Airports Company | K13: 3 | L13: 2 | M13: Keynote Stage 2 (Pavilion 2) | N13: Pavilion 2 | O13: Keynote Stage 2 (Pavilion 2) | P13: How can airports manage growth and capacity through both infrastructure development and smarter use of existing assets? • As traffic rises, how do we maintain operational resilience while protecting the passenger experience? • How can better coordination across airlines, airports and ground handlers reduce operational complexity? • As competition between hubs intensifies, how can airports differentiate through efficiency, technology and experience? • What investments in infrastructure, operations and digital capability will define the most competitive airports over the next 3-5 years?
A14: 13 | B14: Day 2 | C14: 0.44791667 | D14: 0.47916667 | E14: Roundtable | F14: Roundtable | G14: Table 01: FLYR Roundtable - Funding the move to Offer & Order: Creating the right time for the right move | H14: Rodrigo López Josh Crandall | I14: Rodrigo López, Josh Crandall | K14: 2 | M14: Roundtable Area (Pavilion 2) | N14: Pavilion 2 | O14: Roundtable area, Pavilion 2 | Q14: 36 | R14: 40 | S14: =R14-Q14 -> 4 | T14: Open
A15: 14 | B15: Day 2 | C15: 0.44791667 | D15: 0.47916667 | E15: Roundtable | F15: Roundtable | G15: Table 2: ATPCO Roundtable - Airline product catalogs: a foundation for retailing at scale | H15: Doug Sharpe Megan Humphries | I15: Doug Sharpe, Megan Humphries | K15: 2 | M15: Roundtable Area (Pavilion 2) | N15: Pavilion 2 | O15: Roundtable area, Pavilion 2 | Q15: 12 | R15: 40 | S15: =R15-Q15 -> 28 | T15: Open
A16: 15 | B16: Day 2 | C16: 0.44791667 | D16: 0.47916667 | E16: Roundtable | F16: Roundtable | G16: Table 3: 15Below - 10 years of deploying AI in aviation: what works, what doesn’t and what we’ve learned | H16: Ali Tredinnick Joe Bennett | I16: Ali Tredinnick, Joe Bennett | K16: 2 | M16: Roundtable Area (Pavilion 2) | N16: Pavilion 2 | O16: Roundtable area, Pavilion 2 | Q16: 50 | R16: 50 | S16: =R16-Q16 -> 0 | T16: Full
A17: 16 | B17: Day 2 | C17: 0.44791667 | D17: 0.47916667 | E17: Roundtable | F17: Roundtable | G17: Table 4: OneReg Roundtable - Continuous confidence: reimagining how aviation compliance works | H17: Billie Moore Angel Matsis | I17: Billie Moore, Angel Matsis | K17: 2 | M17: Roundtable Area (Pavilion 2) | N17: Pavilion 2 | O17: Roundtable area, Pavilion 2 | Q17: 7 | R17: 40 | S17: =R17-Q17 -> 33 | T17: Open
A18: 17 | B18: Day 2 | C18: 0.44791667 | D18: 0.47916667 | E18: Roundtable | F18: Roundtable | G18: Table 5: Seatboost Roundtable - The gate-side goldmine: Gamification, dynamic pricing, and monetizing the premium cabin | H18: Kevin Stamler | I18: Kevin Stamler | K18: 1 | M18: Roundtable Area (Pavilion 2) | N18: Pavilion 2 | O18: Roundtable area, Pavilion 2 | Q18: 18 | R18: 40 | S18: =R18-Q18 -> 22 | T18: Open
A19: 18 | B19: Day 2 | C19: 0.44791667 | D19: 0.47916667 | E19: Roundtable | F19: Roundtable | G19: Table 6: Ping Identity Roundtable - Whose agent is it anyway? | H19: Alexander Laurie Emanuela Maftieu | I19: Alexander Laurie, Emanuela Maftieu | K19: 2 | M19: Roundtable Area (Pavilion 2) | N19: Pavilion 2 | O19: Roundtable area, Pavilion 2 | Q19: 1 | R19: 40 | S19: =R19-Q19 -> 39 | T19: Open
A20: 19 | B20: Day 2 | C20: 0.44791667 | D20: 0.47916667 | E20: Roundtable | F20: Roundtable | G20: Table 7: ADA Roundtable - Agentic IROPs: Turning flight re-accom into your biggest loyalty moment | H20: Mike Murchison Tatiana Deabreu | I20: Mike Murchison, Tatiana Deabreu | K20: 2 | M20: Roundtable Area (Pavilion 2) | N20: Pavilion 2 | O20: Roundtable area, Pavilion 2 | Q20: 31 | R20: 40 | S20: =R20-Q20 -> 9 | T20: Open
A21: 20 | B21: Day 2 | C21: 0.44791667 | D21: 0.47916667 | E21: Roundtable | F21: Roundtable | G21: Table 8: Lufthansa Industry Solutions Roundtable - How airports, airlines and partners can create value through collaboration | H21: Karina Mehl Michael Kleinert | I21: Karina Mehl, Michael Kleinert | K21: 2 | M21: Roundtable Area (Pavilion 2) | N21: Pavilion 2 | O21: Roundtable area, Pavilion 2 | Q21: 40 | R21: 40 | S21: =R21-Q21 -> 0 | T21: Full
A22: 21 | B22: Day 2 | C22: 0.44791667 | D22: 0.47916667 | E22: Roundtable | F22: Roundtable | G22: Table 9: Chubb Roundtable - When delays happen, payouts shouldn't wait. Using parametrics to turn flight disruption into passenger loyalty. | H22: Ruben Rivero | I22: Ruben Rivero | K22: 1 | M22: Roundtable Area (Pavilion 2) | N22: Pavilion 2 | O22: Roundtable area, Pavilion 2 | Q22: 9 | R22: 40 | S22: =R22-Q22 -> 31 | T22: Open
A23: 22 | B23: Day 2 | C23: 0.44791667 | D23: 0.47916667 | E23: Roundtable | F23: Roundtable | G23: Table10: Intellicene Roundtable - The connected airport: Turning data into operational intelligence | H23: Matthew Maychrowitz Rebecca Rea | I23: Matthew Maychrowitz, Rebecca Rea | K23: 2 | M23: Roundtable Area (Pavilion 2) | N23: Pavilion 2 | O23: Roundtable area, Pavilion 2 | Q23: 26 | R23: 40 | S23: =R23-Q23 -> 14 | T23: Open
A24: 23 | B24: Day 2 | C24: 0.44791667 | D24: 0.47916667 | E24: Roundtable | F24: Roundtable | G24: Table11: Thoughtspot Roundtable - From Insight to Action: How aviation leaders are scaling agentic analytics | H24: James Davies Charlotte Ross | I24: James Davies, Charlotte Ross | K24: 2 | M24: Roundtable Area (Pavilion 2) | N24: Pavilion 2 | O24: Roundtable area, Pavilion 2 | Q24: 23 | R24: 40 | S24: =R24-Q24 -> 17 | T24: Open (you are registered)
A25: 24 | B25: Day 2 | C25: 0.44791667 | D25: 0.47916667 | E25: Roundtable | F25: Roundtable | G25: Table12: Volantio Roundtable - Beyond the AI hype: Can agents finally connect revenue, operations and customer experience? | H25: Ana Maria Escobar Azim Barodawala | I25: Ana Maria Escobar, Azim Barodawala | K25: 2 | M25: Roundtable Area (Pavilion 2) | N25: Pavilion 2 | O25: Roundtable area, Pavilion 2 | Q25: 13 | R25: 40 | S25: =R25-Q25 -> 27 | T25: Open
... A33: 32 | B33: Day 2 | C33: 0.44791667 | D33: 0.47916667 | E33: Roundtable | F33: Roundtable | G33: Table20: Zingly Roundtable - Case study: AI in production at Pegasus Airlines: Beyond deflection to completed passenger journeys | H33: Baris Findik Gaurav Passi | I33: Baris Findik, Gaurav Passi | K33: 2 | M33: Roundtable Area (Pavilion 2) | N33: Pavilion 2 | O33: Roundtable area, Pavilion 2 | Q33: 10 | R33: 40 | S33: =R33-Q33 -> 30 | T33: Open
A34: 33 | B34: Day 2 | C34: 0.47916667 | E34: Networking | F34: Networking | G34: Aviation Connect: Session 3 | H34: Host, World Aviation Festival | I34: Host | J34: World Aviation Festival | K34: 1 | M34: Aviation Connect Zone (Pavilion 2) | N34: Pavilion 2 | O34: Aviation Connect Zone Pavilion 2 | P34: Aviation Connect is our dedicated networking hour. Book 15 minute meetings via the Aviation Connect Platform and make the most of your time at WAF. No other sessions, workshops or activities are taking place during this time.
A35: 34 | B35: Day 2 | C35: 0.51736111 | E35: Loyalty | F35: Chair Remarks | G35: Chair opening remarks | H35: Harald Deprosse – Partner, Envolved GmbH | I35: Harald Deprosse | J35: Envolved GmbH | K35: 1 | M35: Track 3 (Pavilion 1) | N35: Pavilion 1 | O35: Track 3 (Pavilion 1)
A36: 35 | B36: Day 2 | C36: 0.52083333 | E36: Sustainability | F36: Fireside Chat | G36: Fireside Chat: Growth without compromise – can airlines decarbonise while remaining competitive? | H36: Maria Whittaker – Chief Corporate Responsibility Officer, Abra Group Patrick Edmond – Chief Commercial Officer, Future Energy Global | I36: Maria Whittaker, Patrick Edmond | J36: Abra Group, Future Energy Global | K36: 2 | M36: Track 10 (Pavilion 2) | N36: Pavilion 2 | O36: Track 10 (Pavilion 2)
A37: 36 | B37: Day 2 | C37: 0.52083333 | E37: Loyalty | F37: Welcome | G37: Plusgrade Welcome | H37: Richard Wolfman – SVP Global Business Development, Plusgrade | I37: Richard Wolfman | J37: Plusgrade | K37: 1 | M37: Track 3 (Pavilion 1) | N37: Pavilion 1 | O37: Track 3, Pav 1
A38: 37 | B38: Day 2 | C38: 0.52430556 | E38: AI / ML | F38: Presentation | G38: Presentation: Building tomorrow’s airline: AI-orchestrated, human-led | H38: Oliver Schmitt – CEO Digital Hangar Ecosystem & SVP Digital Solutions, Lufthansa Group Digital Hangar GmbH | I38: Oliver Schmitt | J38: Lufthansa Group Digital Hangar GmbH | K38: 1 | M38: Track 9 (Pavilion 2) | N38: Pavilion 2 | O38: Track 9, Pavilion 2
A39: 38 | B39: Day 2 | C39: 0.52430556 | E39: Customer Experience | F39: Talk | G39: Human connection, effortless digital experiences: premium CX in the age of AI | H39: Bethan Lynch – VP Customer Experience & Loyalty, Virgin Atlantic Jerry Angrave – Customer Experience Director, Empathyce | I39: Bethan Lynch, Jerry Angrave | J39: Virgin Atlantic, Empathyce | K39: 2 | M39: Track 2 (Pavilion 1) | N39: Pavilion 1 | O39: Track 2 (Pavilion 1) | P39: AI will transform how consumers plan, shop and make the most of travel. But what does the future look like for premium travellers who expect personalised, memorable experiences and genuine emotional connection? • In this fireside chat, Virgin Atlantic’s VP Customer Experience & Loyalty, Bethan Lynch, joins Jerry Angrave to share how the airline is embracing innovative use of AI to serve its customers more personally and seamlessly, while upholding its unique culture, built around its people and their unmistakeable warmth and flair. On its journey to become the most loved travel company, Bethan will explain how Virgin Atlantic sees AI as an extension of the human-centred experience. An opportunity to remove friction and make every interaction meaningful and distinctly Virgin, while enabling people to do what only people can do: create trust, build connection and make customers feel genuinely cared for. • Combining humanity with innovation, also hear how Virgin Atlantic is doubling down on its premium experience across the customer journey, including the rollout of free, high speed Starlink Wi-Fi, new expanded Upper and Premium cabins, investment in award-winning Clubhouses, and a new app integrated with Virgin Atlantic Concierge, powered by OpenAI and built in partnership with Tomoro. Through its brand, people, and the award-winning experience they deliver, Virgin Atlantic is creating emotional connections that last long after the journey ends – building loyalty and enticing customers to choose Virgin Atlantic time and again.
A40: 39 | B40: Day 2 | C40: 0.52430556 | E40: Loyalty | F40: Fireside Chat | G40: Fireside Chat: The future outlook for loyalty at Abra Group | H40: Ralph Piket – Chief Loyalty Officer, Abra Group Harald Deprosse – Partner, Envolved GmbH | I40: Ralph Piket, Harald Deprosse | J40: Abra Group, Envolved GmbH | K40: 2 | M40: Track 3 (Pavilion 1) | N40: Pavilion 1 | O40: Track 3, Pavilion 1
A41: 40 | B41: Day 2 | C41: 0.52430556 | E41: IROPS | F41: Presentation | G41: Presentation: Project ConnectOps: Delivering highly contextualised and realtime information to optimise insights for crew, airport and operational staff | H41: Rachel Gaud – Ops Digital Transformation Lead, Etihad | I41: Rachel Gaud | J41: Etihad | K41: 1 | M41: Track 4 (Pavilion 1) | N41: Pavilion 1 | O41: Track 4 (Pavilion 1)
A42: 41 | B42: Day 2 | C42: 0.52430556 | E42: Digital & IT | F42: Fireside Chat | G42: Fireside Chat: From mainframe to cloud: Air Canada’s modernisation playbook | H42: Mel Crocker – CIO, Air Canada David Peller – General Partner & Founder, If Not You Capital | I42: Mel Crocker, David Peller | J42: Air Canada, If Not You Capital | K42: 2 | M42: Track 1 (Pavilion 1) | N42: Pavilion 1 | O42: Track 1(Pavilion 1)
A43: 42 | B43: Day 2 | C43: 0.52430556 | E43: Airport - Operations | F43: Presentation | G43: Presentation: Becoming a more data driven airport system – collaboration between all stakeholders | H43: Samuel C. Ehrat – Senior Project Leader, Zurich Airport Lorenz Wolf – ICT Solution Architect, Zurich Airport | I43: Samuel C. Ehrat, Lorenz Wolf | J43: Zurich Airport | K43: 2 | M43: Track 8 (Pavilion 2) | N43: Pavilion 2 | O43: Track 8 (Pavilion 2)
A44: 43 | B44: Day 2 | C44: 0.52430556 | E44: Airport & Airline Collaboration | F44: Presentation | G44: Presentation: Lisette Looren de Jong-Vonk, Programme Manager Innovation Border Management, Ministry of Justice and Security – The Netherlands | H44: Lisette Looren de Jong – Programme Manager Innovation Border Management, Ministry of Justice and Security | I44: Lisette Looren de Jong | J44: Ministry of Justice and Security | K44: 1 | M44: Keynote Stage 2 (Pavilion 2) | N44: Pavilion 2 | O44: Keynote Stage 2 (Pavilion 2)
A45: 44 | B45: Day 2 | C45: 0.52430556 | E45: Airport - Traveller | F45: Presentation | G45: Presentation: Building the digital airport – using mobile and AI assistance to bridge the digital and physical airport experience | H45: Jorn Korbi – VP Digital Commercialization, Avinor | I45: Jorn Korbi | J45: Avinor | K45: 1 | M45: Track 7 (Pavilion 2) | N45: Pavilion 2 | O45: Track 7 (Pavilion 2)
A46: 45 | B46: Day 2 | C46: 0.52430556 | E46: Retail | F46: Fireside Chat | G46: Fireside Chat: Legacy to leader: What cultural and digital shift does the industry need for a modern retail transition? | H46: Julio Rodriguez – Chief Commercial Strategy Officer, IAG Dennis Cary – Managing Director, Cary Strategic Advisory | I46: Julio Rodriguez, Dennis Cary | J46: IAG, Cary Strategic Advisory | K46: 2 | M46: Track 5 (Pavilion 1) | N46: Pavilion 1 | O46: Track 5 (Pavilion 1)
A47: 46 | B47: Day 2 | C47: 0.52430556 | E47: Payments | F47: Presentation | G47: Presentation: The hardest part of Offer & Order is not Offer & Order | H47: Ozan Berk Karataş – Senior Program Manager, Airline Retailing & Payments, Turkish Airlines | I47: Ozan Berk Karataş | J47: Turkish Airlines | K47: 1 | M47: Track 6 (Pavilion 1) | N47: Pavilion 1 | O47: Track 6 (Pavillion 1)
...

Sheet Day 3
A1: # | B1: Day | C1: Start | D1: End | E1: Stream / Category | F1: Format | G1: Session Title | H1: Speakers (Name – Job Title, Company) | I1: Speaker Names | J1: Organisations | K1: Speakers Listed | L1: Additional Speakers (not shown on site) | M1: Room / Stage | N1: Pavilion | O1: Room (as listed on site) | P1: Description / Discussion Points | Q1: Registered | R1: Capacity | S1: Places Left | T1: Registration Status
A2: 1 | B2: Day 3 | E2: Networking | F2: Networking | G2: Aviation Connect: Session 7 | H2: Host, World Aviation Festival | I2: Host | J2: World Aviation Festival | K2: 1 | M2: Aviation Connect Zone (Pavilion 2) | N2: Pavilion 2 | O2: Aviation Connect Zone, Pavilion 2
A3: 2 | B3: Day 3 | C3: 0.39583333 | E3: Airline Keynote | F3: Talk | G3: Fast & Slow Social: Driving engagement with smart social media strategy | H3: Michael Corcoran – Co-Founder, Slice Social Oisin Lunny – Event MC, Journalist, Podcast and Webinar Host, Galaxy of OM, S.L. | I3: Michael Corcoran, Oisin Lunny | J3: Slice Social, Galaxy of OM, S.L. | K3: 2 | M3: Keynote Stage 1 (Pavilion 1) | N3: Pavilion 1 | O3: Keynote Stage 1 (Pavilion 1)
A4: 3 | B4: Day 3 | C4: 0.40625 | E4: Airport Keynote | F4: Interview | G4: Keynote Interview with Lars Redeligx, CEO, Düsseldorf Airport | H4: Lars Redeligx – CEO, Dusseldorf Airport Luis Felipe De Oliveira – Executive Director and CEO, Exactly Consulting and Services Sarl | I4: Lars Redeligx, Luis Felipe De Oliveira | J4: Dusseldorf Airport, Exactly Consulting and Services Sarl | K4: 2 | M4: Keynote Stage 2 (Pavilion 2) | N4: Pavilion 2 | O4: Keynote Stage 2 (Pavilion 2)
A5: 4 | B5: Day 3 | C5: 0.40625 | E5: Airline Keynote | F5: Fireside Chat | G5: Fireside Chat with Amy Burr, CEO, SKY VC | H5: Amy Burr – CEO, SKY VC Lennart Dobravsky – Managing Director, Research+Attitude | I5: Amy Burr, Lennart Dobravsky | J5: SKY VC, Research+Attitude | K5: 2 | M5: Keynote Stage 1 (Pavilion 1) | N5: Pavilion 1 | O5: Keynote Stage 1 (Pavilion 1)
A6: 5 | B6: Day 3 | C6: 0.41666667 | E6: Airport Keynote | F6: Panel | G6: Keynote Panel: Defining the airport of the future – technology, partnerships and people | H6: Lars Redeligx – CEO, Dusseldorf Airport Olubunmi Kuku – Managing Director/Chief Executive, FEDERAL AIRPORTS AUTHORITY OF NIGERIA Javlonbek Umarkhodjaev – Chairman of the Management Board, Uzbekistan Airports JSC | I6: Lars Redeligx, Olubunmi Kuku, Javlonbek Umarkhodjaev | J6: Dusseldorf Airport, FEDERAL AIRPORTS AUTHORITY OF NIGERIA, Uzbekistan Airports JSC | K6: 3 | L6: 1 | M6: Keynote Stage 2 (Pavilion 2) | N6: Pavilion 2 | O6: Keynote Stage 2 (Pavilion 2) | P6: How are airports evolving beyond transport infrastructure into mobility, economic and community hubs? • As automation and digital services expand, how do we preserve the human side of travel? • What role do airlines, airports and ground handlers each play in shaping the passenger journey? • How can the industry collaborate more effectively to deliver growth, resilience and sustainability? • What will distinguish the leading airports of the next decade?
A7: 6 | B7: Day 3 | C7: 0.41666667 | E7: Airline Keynote | F7: Panel | G7: Investor Panel: Innovation at a crossroads – where are aviation’s next big bets? | H7: Amy Burr – CEO, SKY VC Cara Whitehill – Operating Partner, Thayer Investment Partners Amir Amidi – Managing Partner, Plug and Play Tech Center | I7: Amy Burr, Cara Whitehill, Amir Amidi | J7: SKY VC, Thayer Investment Partners, Plug and Play Tech Center | K7: 3 | L7: 2 | M7: Keynote Stage 1 (Pavilion 1) | N7: Pavilion 1 | O7: Keynote Stage 1 (Pavilion 1)
A8: 7 | B8: Day 3 | C8: 0.44791667 | E8: Networking | F8: Networking | G8: Aviation Connect: Session 5 | H8: Host, World Aviation Festival | I8: Host | J8: World Aviation Festival | K8: 1 | M8: Aviation Connect Zone (Pavilion 2) | N8: Pavilion 2 | O8: Aviation Connect Zone, Pavilion 2 | P8: Aviation Connect is our dedicated networking hour. Book 15 minute meetings via the Aviation Connect Platform and make the most of your time at WAF. No other sessions, workshops or activities are taking place during this time.
A9: 8 | B9: Day 3 | C9: 0.49305556 | E9: Startup Theatre | F9: Startup Pitch | G9: Your chatbot knows everything. Except how to help. | H9: Tiernan Mines – CEO & Co-Founder, Hello Airport | I9: Tiernan Mines | J9: Hello Airport | K9: 1 | M9: Startup Theatre | O9: Startup Theatre
A10: 9 | B10: Day 3 | C10: 0.49652778 | E10: Loyalty | F10: Chair Remarks | G10: Chair opening remarks | H10: Harald Deprosse – Partner, Envolved GmbH | I10: Harald Deprosse | J10: Envolved GmbH | K10: 1 | M10: Track 3 (Pavilion 1) | N10: Pavilion 1 | O10: Track 3 (Pavillion 1)
A11: 10 | B11: Day 3 | C11: 0.5 | E11: Digital & IT | F11: Fireside Chat | G11: Fireside Chat: Executing Offer & Order – balancing innovation with operational reality | H11: Dan Fischer – Head of Digital Product, Strategy & Design, Virgin Australia Mark Lenahan – Consultant, Lenahan Consulting Ltd | I11: Dan Fischer, Mark Lenahan | J11: Virgin Australia, Lenahan Consulting Ltd | K11: 2 | M11: Track 1 (Pavilion 1) | N11: Pavilion 1 | O11: Track 1(Pavilion 1)
A12: 11 | B12: Day 3 | C12: 0.5 | E12: Startup Theatre | F12: Startup Pitch | G12: The Growing Threat of Brand Hijacking to Airline Direct Bookings | H12: Shlomi Beer – Co-founder & CEO, ImpersonAlly | I12: Shlomi Beer | J12: ImpersonAlly | K12: 1 | M12: Startup Theatre | O12: Startup Theatre
A13: 12 | B13: Day 3 | C13: 0.5 | E13: Airline Keynote | F13: Interview | G13: CEO Interview: Eivind Roald, CEO, Norse Atlantic Airlines | H13: Eivind Roald – President & CEO, Norse Atlantic Airways John Strickland – Director, JLS Consulting | I13: Eivind Roald, John Strickland | J13: Norse Atlantic Airways, JLS Consulting | K13: 2 | M13: Keynote Stage 1 (Pavilion 1) | N13: Pavilion 1 | O13: Keynote Stage 1 (Pavilion 1)
A14: 13 | B14: Day 3 | C14: 0.5 | E14: Airport & Airline Collaboration | F14: Fireside Chat | G14: Fireside Chat: Beyond AODP - redesigning the airport’s digital foundation | H14: Iyad Hindiyeh – CDO, GAL - GMR Group Maurice Jenkins – Chief Innovation Officer, Miami International Airport | I14: Iyad Hindiyeh, Maurice Jenkins | J14: GAL - GMR Group, Miami International Airport | K14: 2 | M14: Keynote Stage 2 (Pavilion 2) | N14: Pavilion 2 | O14: Keynote Stage 2 (Pavilion 2)
A15: 14 | B15: Day 3 | C15: 0.5 | E15: Loyalty | F15: Presentation | G15: Presentation: How should an airline’s loyalty program position itself within the airline for maximum impact? | H15: Tiffany Funk – Head of Flying Blue, VP Loyalty, Air France KLM | I15: Tiffany Funk | J15: Air France KLM | K15: 1 | M15: Track 3 (Pavilion 1) | N15: Pavilion 1 | O15: Track 3 (Pavillion 1)
A16: 15 | B16: Day 3 | C16: 0.5 | E16: AI / ML | F16: Talk | G16: The agentic Airline of the future: Lessons from Air India’s enterprise AI journey | H16: Murali Karthik – Head of EA, Governance, Data & AI, Agentic COE, Air India | I16: Murali Karthik | J16: Air India | K16: 1 | M16: Track 9 (Pavilion 2) | N16: Pavilion 2 | O16: Track 9 (Pavilion 2)
A17: 16 | B17: Day 3 | C17: 0.5 | E17: Retail | F17: Presentation | G17: Presentation: Disrupting the status quo: Air Europa’s successful distribution journey | H17: Yago Casasnovas – Head of Payments, Fraud Prevention and Distribution, Air Europa Daniel Langhage – Managing Director, Oystin Advisory GmbH | I17: Yago Casasnovas, Daniel Langhage | J17: Air Europa, Oystin Advisory GmbH | K17: 2 | M17: Track 5 (Pavilion 1) | N17: Pavilion 1 | O17: Track 5 (Pavilion 1)
A18: 17 | B18: Day 3 | C18: 0.5 | E18: Airport - Operations | F18: Presentation | G18: Presentation: Gear Up NRT | H18: Yusuke Izawa – Project Manager, Global Business Department, Narita International Airport Corp. | I18: Yusuke Izawa | J18: Narita International Airport Corp. | K18: 1 | M18: Track 8 (Pavilion 2) | N18: Pavilion 2 | O18: Track 8 (Pavilion 2) | P18: Expanding Capacity, Driving Innovation, Overseas Business
A19: 18 | B19: Day 3 | C19: 0.50694444 | E19: Startup Theatre | F19: Startup Pitch | G19: Making better commercial decisions in a world that's never been more complicated | H19: Alex Matson – COO, telos | I19: Alex Matson | J19: telos | K19: 1 | M19: Startup Theatre | O19: Startup Theatre
A20: 19 | B20: Day 3 | C20: 0.51041667 | E20: AI / ML | F20: Presentation | G20: Presentation: Agentic AI and the future of airline competitiveness | H20: Lars Schwabe – Chief Technology Officer, Lufthansa Industry Solutions | I20: Lars Schwabe | J20: Lufthansa Industry Solutions | K20: 1 | M20: Track 9 (Pavilion 2) | N20: Pavilion 2 | O20: Track 9 (Pavilion 2)
A21: 20 | B21: Day 3 | C21: 0.51041667 | E21: Airport - Operations | F21: Panel | G21: Panel: Scaling airport innovation – moving from pilot projects to operational deployment | H21: Vanesa Calvo – Head of Funding and Innovation Trends, A.E.N.A. Sanne Cox – Innovation Manager, Royal Schiphol Group Eric Boromisa – Founder | Managing Partner, Numbers & Letters Advisory | I21: Vanesa Calvo, Sanne Cox, Eric Boromisa | J21: A.E.N.A., Royal Schiphol Group, Numbers & Letters Advisory | K21: 3 | M21: Track 8 (Pavilion 2) | N21: Pavilion 2 | O21: Track 8 (Pavilion 2) | P21: Airports are piloting more tools than ever across AI, automation, robotics and digital passenger services. What actually moves beyond the pilot stage? • Capacity constraints are forcing airports to get more from existing infrastructure. Where is innovation delivering the biggest operational gains? • Some innovations reduce cost, some improve experience, and some create new revenue. How do airports decide what matters most? • What internal conditions really determine whether an innovation scale – governance, funding, culture or partner buy-in? • Looking ahead, where should airports be placing their smartest innovation bets?
A22: 21 | B22: Day 3 | C22: 0.51041667 | E22: Retail | F22: Fireside Chat | G22: Fireside Chat: From infrastructure to intelligence: How ATPCO is building airline retailing's AI-ready foundation | H22: Anand Mishra – VP of Technology, ATPCO Sinead Finn – Founder, affinnity | I22: Anand Mishra, Sinead Finn | J22: ATPCO, affinnity | K22: 2 | M22: Track 5 (Pavilion 1) | N22: Pavilion 1 | O22: Track 5 (Pavilion 1) | P22: Airline retailing is being fundamentally reimagined and the companies that will shape its future aren't just building smarter products, they're building smarter foundations. ATPCO Vice President of Technology Anand Mishra will explore how the industry's most trusted neutral data layer is evolving to meet the moment, as agentic AI moves from concept to commercial reality. With nearly two-thirds of adult travelers under 45 already turning to AI for travel recommendations and AI-driven booking accelerating fast, the window to establish trusted, structured data foundations is open, but for how long? • Anand will pull back the curtain on recent ATPCO's experiments: including those that ask a simple but high-stakes question — can ATPCO's structured data turn general AI into a trusted source for airline retailing? The answer was a resounding yes, and Anand will dive into some of the learnings. • Attendees will leave with a clear view of where airline retailing's AI transformation is heading over the next 18 to 36 months, why the standards and data layer will be the defining battleground, and how ATPCO is positioning itself, and the industry, to make sure that transformation happens for us, not to us
A23: 22 | B23: Day 3 | C23: 0.51041667 | E23: Digital & IT | F23: Talk | G23: FROM FILED FARES TO FLEXIBLE FUTURES OF FARE FILING - MODERNIZE TODAY. BUILD TOMORROW | H23: Christoph Both – Head of Customer, Business Development & Controlling, Lufthansa Process Management | I23: Christoph Both | J23: Lufthansa Process Management | K23: 1 | M23: Track 1 (Pavilion 1) | N23: Pavilion 1 | O23: Track 1(Pavilion 1)
A24: 23 | B24: Day 3 | C24: 0.51041667 | E24: Airport & Airline Collaboration | F24: Presentation | G24: Presentation: 638 Days to Go: Transforming the LAX Passenger Experience for the 2028 Olympics and Paralympics | H24: Erin Trapp – Chief Strategy & External Affairs Officer, Los Angeles World Airports | I24: Erin Trapp | J24: Los Angeles World Airports | K24: 1 | M24: Keynote Stage 2 (Pavilion 2) | N24: Pavilion 2 | O24: Keynote Stage 2 (Pavilion 2)
A25: 24 | B25: Day 3 | C25: 0.51041667 | E25: Loyalty | F25: Presentation | G25: Presentation: Beyond miles and seats: building the future of travel loyalty | H25: Ofir Goldman – Director of Global Marketing & Digital, EL AL Israel Airlines Benny Yonovich – Co-Founder & CEO, Arbitrip | I25: Ofir Goldman, Benny Yonovich | J25: EL AL Israel Airlines, Arbitrip | K25: 2 | M25: Track 3 (Pavilion 1) | N25: Pavilion 1 | O25: Track 3 (Pavillion 1) | P25: How can airlines turn hotel bookings into a new engine for growth? EL AL and Arbitrip will share the story behind EL AL Travel, showcasing how their partnership brings hotels into the airline’s core offering. The session will explore how airlines can expand beyond flights, generate incremental revenue from hotels and ancillary services, and strengthen customer loyalty by making the entire travel experience part of their brand.
A26: 25 | B26: Day 3 | C26: 0.51388889 | E26: Startup Theatre | F26: Startup Pitch | G26: Crew Feedback: From Qualitative to Quantitative Data | H26: Tuur Willio – Junior Commercial Associate, JiGSO | I26: Tuur Willio | J26: JiGSO | K26: 1 | M26: Startup Theatre | O26: Startup Theatre
A27: 26 | B27: Day 3 | C27: 0.52083333 | E27: Digital & IT | F27: Panel | G27: Panel: Delivering modern airline retailing – how do we make offer & order work? | H27: Jörg Ahrens – Head of IT Commercial Systems, Condor Flugdienst GmbH Bhaskara Guntreddy – Senior Vice President, Product, PROS Marco Contento – VP Aviation Business Services, IBS Software | I27: Jörg Ahrens, Bhaskara Guntreddy, Marco Contento | J27: Condor Flugdienst GmbH, PROS, IBS Software | K27: 3 | L27: 2 | M27: Track 1 (Pavilion 1) | N27: Pavilion 1 | O27: Track 1(Pavilion 1) | P27: Where are airlines actually live with Offer & Order today - and what has it taken to get there? • How are teams connecting commercial, distribution and IT to move from roadmap to delivery? • What are the toughest integration challenges across PSS, pricing, payments and fulfilment? How do we work through these? • What delivery models are emerging - phased rollouts, parallel systems or full migration? • What defines success when modern airline retailing is fully embedded into core systems?
A28: 27 | B28: Day 3 | C28: 0.52083333 | E28: Retail | F28: Panel | G28: Panel: Dynamic bundling: Rethinking systems and products for the intuitive traveller | H28: Tiddo Veldhuis – VP Offer Management & Ancillaries, Air France KLM Sharon Huetson – Head of Proposition, easyJet Jay Sorensen – President, IdeaWorksCompany | I28: Tiddo Veldhuis, Sharon Huetson, Jay Sorensen | J28: Air France KLM, easyJet, IdeaWorksCompany | K28: 3 | L28: 1 | M28: Track 5 (Pavilion 1) | N28: Pavilion 1 | O28: Track 5 (Pavilion 1) | P28: Moving away from rigid "Basic/Flex" fare structures toward AI-generated bundles created on-the-fly based on real-time traveller intent • Navigating personalised pricing to ensure it remains a value-add rather than a regulatory or reputational risk • Strategies for seamlessly integrating lifestyle and non-air ancillaries, such as hotels, tours, and carbon offsets, into the initial booking flow • Why has personalisation historically failed to meet expectations and do personalisation tactics in ancillary sales need a rethink?
A29: 28 | B29: Day 3 | C29: 0.52083333 | E29: Airport & Airline Collaboration | F29: Panel | G29: Panel: Who owns the passenger & captures the value – and are airports and airlines ready for co-ownership? | H29: Arturs Saveljevs – Board member and CCO, Riga International Airport Iyad Hindiyeh – CDO, GAL - GMR Group Mihai Tica – CIO, Dusseldorf Airport | I29: Arturs Saveljevs, Iyad Hindiyeh, Mihai Tica | J29: Riga International Airport, GAL - GMR Group, Dusseldorf Airport | K29: 3 | L29: 2 | M29: Keynote Stage 2 (Pavilion 2) | N29: Pavilion 2 | O29: Keynote Stage 2 (Pavilion 2) | P29: Who truly owns passenger data across the journey - and how does that ownership shift between booking, airport and arrival? • What is the real commercial upside of sharing data and which joint revenue opportunities (retail, e-commerce, ancillaries) depend on it? • Where do competitive sensitivities, loyalty programmes and margin pressures still block deeper collaboration? • Can airports build meaningful data platforms without airlines or is joint architecture across airlines, alliances and groups of airports essential? • Looking ahead, will passenger data sit in collaborative platforms, or remain siloed within airline and airport ecosystems?
A30: 29 | B30: Day 3 | C30: 0.52083333 | E30: Loyalty | F30: Talk | G30: Unpacking the next evolution of AI and personalisation within airline loyalty | H30: Tiffany Funk – Head of Flying Blue, VP Loyalty, Air France KLM Omer Faruk Sonmez – Senior Vice President Marketing, Turkish Airlines Nejib Ben-Khedher – Divisional Senior Vice President, Skywards, EMIRATES GROUP | I30: Tiffany Funk, Omer Faruk Sonmez, Nejib Ben-Khedher | J30: Air France KLM, Turkish Airlines, EMIRATES GROUP | K30: 3 | L30: 3 | M30: Track 3 (Pavilion 1) | N30: Pavilion 1 | O30: Track 3 (Pavillion 1) | P30: Moving beyond tier-based recognition • Using loyalty data when the journey goes wrong • Extending member value across the travel ecosystem • Taking AI-powered loyalty from isolated use cases to scale
A31: 30 | B31: Day 3 | C31: 0.52083333 | E31: AI / ML | F31: Presentation | G31: Presentation: One memory, every touchpoint: How AI can connect the traveller journey from app to gate to seat | H31: Mahesh Veda – Managing Director, United Airlines Raj Sivakumar – Corporate Senior Vice President, WNS Global Services (UK) Limited | I31: Mahesh Veda, Raj Sivakumar | J31: United Airlines, WNS Global Services (UK) Limited | K31: 2 | M31: Track 9 (Pavilion 2) | N31: Pavilion 2 | O31: Track 9 (Pavilion 2) | P31: Every airline delivers personalization across multiple channels, but continuity often breaks as the traveler moves from one touchpoint to another. • What changes when AI moves beyond recommending and starts anticipating? • In this session, Mahesh Veda of United Airlines and Jitender Mohan of WNS will explore how airlines can create a connected, context-aware understanding of each traveler across the app, airport, gate and onboard experience. • The discussion will examine how AI, loyalty data and real-time customer insight can come together to simplify journeys, strengthen engagement and unlock new revenue opportunities. • Key Themes • Moving from channel-level personalization to journey-level continuity • Using AI to anticipate traveler needs and determine the next best action • Connecting digital, airport and onboard experiences • Bringing together eCommerce, loyalty, customer data and operations • Converting personalization into stronger engagement, loyalty and enterprise value
A32: 31 | B32: Day 3 | C32: 0.52083333 | E32: Startup Theatre | F32: Startup Pitch | G32: Insights from deploying AI across 50'000 flights per month | H32: Nikita Kaeshko – Co-founder, Overwatch AI | I32: Nikita Kaeshko | J32: Overwatch AI | K32: 1 | M32: Startup Theatre | O32: Startup Theatre
A33: 32 | B33: Day 3 | C33: 0.52777778 | E33: Startup Theatre | F33: Startup Pitch | G33: What a System of Action can do for an Airline | H33: Jim Stathopoulos – Co-founder, dCortex | I33: Jim Stathopoulos | J33: dCortex | K33: 1 | M33: Startup Theatre | O33: Startup Theatre
A34: 33 | B34: Day 3 | C34: 0.53125 | E34: AI / ML | F34: Panel | G34: Panel: Discussing the challenges of driving successful strategic AI adoption, impactful solutions and evaluating the financial return | H34: Ivan Karlovic – Director of data, analytics, and AI, Norwegian Kushal Pasari – Director - AI/ML Engineering & Platforms, United Airlines Tauseef Khan – Manager of Data & AI, Air Canada | I34: Ivan Karlovic, Kushal Pasari, Tauseef Khan | J34: Norwegian, United Airlines, Air Canada | K34: 3 | L34: 2 | M34: Track 9 (Pavilion 2) | N34: Pavilion 2 | O34: Track 9 (Pavilion 2) | P34: How can airlines lay the foundations for effective AI implementation in a rapidly evolving ecosystem? • Working across the business to evaluate impactful opportunities for AI powered solutions to change the game • How are airlines planning to scale data-science powered innovation effectively?
A35: 34 | B35: Day 3 | C35: 0.53472222 | E35: Startup Theatre | F35: Startup Pitch | G35: SeatMaps of Record: data & visualizations for airlines and channel. | H35: Terje Tjostolvsen – Adviser, Seatmaps Ltd | I35: Terje Tjostolvsen | J35: Seatmaps Ltd | K35: 1 | M35: Startup Theatre | O35: Startup Theatre
A36: 35 | B36: Day 3 | C36: 0.54166667 | E36: Startup Theatre | F36: Startup Pitch | G36: Building ReLUGG - solving your own problem as a founder | H36: Melilizwe Gqobo – CEO & Co-founder, ReLUGG | I36: Melilizwe Gqobo | J36: ReLUGG | K36: 1 | M36: Startup Theatre | O36: Startup Theatre
A37: 36 | B37: Day 3 | C37: 0.54861111 | E37: Startup Theatre | F37: Startup Pitch | G37: AEROMOND – The Next-Gen On-Board Service Experience | H37: Sebastian Pruckmair – Founder & CEO, AEROMOND Services e.u. | I37: Sebastian Pruckmair | J37: AEROMOND Services e.u. | K37: 1 | M37: Startup Theatre | O37: Startup Theatre
A38: 37 | B38: Day 3 | C38: 0.55208333 | D38: 0.59375 | E38: Workshop | F38: Workshop | G38: Portugal in the Future Aviation Ecosystem: Clean Aviation, AAM & MR **Registration required | H38: Rui Santos Jose Rui Marcelino Margarida Pinto Dário Pedro Nelson Vaz David Cruz | I38: Rui Santos, Jose Rui Marcelino, Margarida Pinto, Dário Pedro, Nelson Vaz, David Cruz | K38: 6 | M38: Track 5 (Pavilion 1) | N38: Pavilion 1 | O38: Track 5, Pavilion 1 | Q38: 26 | R38: 50 | S38: =R38-Q38 -> 24 | T38: Open
A39: 38 | B39: Day 3 | C39: 0.55555556 | E39: Startup Theatre | F39: Startup Pitch | G39: Beyond the Forecast: Turning Weather into Aviation Intelligence | H39: Sevim Aydın Kotil – Head of Business Development, Buluttan Weather Intelligence | I39: Sevim Aydın Kotil | J39: Buluttan Weather Intelligence | K39: 1 | M39: Startup Theatre | O39: Startup Theatre
A40: 39 | B40: Day 3 | C40: 0.5625 | E40: Airline Keynote | F40: Competition | G40: Competition: Ancillary Arena | H40: Beatriz Guillen – Chief Customer Officer, Iberia Surya Kuchibotla – VP eCommerce, Ancillary and Retailing, OMAN AIR Lissette Castaneda – Head of Ancillary Revenue, Tap Air Portugal | I40: Beatriz Guillen, Surya Kuchibotla, Lissette Castaneda | J40: Iberia, OMAN AIR, Tap Air Portugal | K40: 3 | L40: 7 | M40: Keynote Stage 1 (Pavilion 1) | N40: Pavilion 1 | O40: Keynote Stage (Pavilion 1) | P40: We are on the hunt for the next big ancillary product or service. Join this session to hear from our 5 finalist companies who will be pitching their solution to our expert panel: • Riyadh Air (PointsXchange) • InterLnkd (NEXORA) • Retailaer • VINI (Flyvbird GmbH) • Roamon
...

Sheet All Sessions
A1: # | B1: Day | C1: Start | D1: End | E1: Stream / Category | F1: Format | G1: Session Title | H1: Speakers (Name – Job Title, Company) | I1: Speaker Names | J1: Organisations | K1: Speakers Listed | L1: Additional Speakers (not shown on site) | M1: Room / Stage | N1: Pavilion | O1: Room (as listed on site) | P1: Description / Discussion Points | Q1: Registered | R1: Capacity | S1: Places Left | T1: Registration Status
A2: 1 | B2: Day 2 | C2: 0.34375 | E2: Networking | F2: Networking | G2: Aviation Connect: Session 6 | H2: Host, World Aviation Festival | I2: Host | J2: World Aviation Festival | K2: 1 | M2: Aviation Connect Zone (Pavilion 2) | N2: Pavilion 2 | O2: Aviation Connect Zone Pavilion 2
A3: 2 | B3: Day 2 | C3: 0.38194444 | E3: Airline Keynote | F3: Welcome | G3: Official Welcome | H3: Carlos Oliveira – Chairman, Tap Air Portugal | I3: Carlos Oliveira | J3: Tap Air Portugal | K3: 1 | M3: Keynote Stage 1 (Pavilion 1) | N3: Pavilion 1 | O3: Keynote Theatre (Pavilion 1)
A4: 3 | B4: Day 2 | C4: 0.38541667 | E4: Airport Keynote | F4: Welcome | G4: Official Airport Partner Welcome | H4: Thierry Ligonnière – Chief Executive Officer, ANA Aeroportos de Portugal | I4: Thierry Ligonnière | J4: ANA Aeroportos de Portugal | K4: 1 | M4: Keynote Stage 2 (Pavilion 2) | N4: Pavilion 2 | O4: Keynote Stage 2 (Pavilion 2)
A5: 4 | B5: Day 2 | C5: 0.38888889 | E5: Airport Keynote | F5: Interview | G5: CEO Interview: Stefan Schulte, CEO, Fraport AG | H5: Stefan Schulte – Chief Executive Officer, Fraport AG Ben Thompson – Presenter, BBC | I5: Stefan Schulte, Ben Thompson | J5: Fraport AG, BBC | K5: 2 | M5: Keynote Stage 2 (Pavilion 2) | N5: Pavilion 2 | O5: Keynote Stage 2 (Pavilion 2)
A6: 5 | B6: Day 2 | C6: 0.38888889 | E6: Airline Keynote | F6: Interview | G6: CEO Interview: Luis Rodrigues, CEO, TAP Air Portugal | H6: Luís Rodrigues – Chief Executive Officer, Tap Air Portugal Peter Campbell – Global Transport Correspondent, Financial Times | I6: Luís Rodrigues, Peter Campbell | J6: Tap Air Portugal, Financial Times | K6: 2 | M6: Keynote Stage 1 (Pavilion 1) | N6: Pavilion 1 | O6: Keynote Stage 1 (Pavilion 1)
A7: 6 | B7: Day 2 | C7: 0.39583333 | E7: Airline Keynote | F7: Interview | G7: CEO Interview: Adrian Neuhauser, CEO, ABRA Group | H7: Adrian Neuhauser – Chief Executive Officer, Abra Group Peter Campbell – Global Transport Correspondent, Financial Times | I7: Adrian Neuhauser, Peter Campbell | J7: Abra Group, Financial Times | K7: 2 | M7: Keynote Stage 1 (Pavilion 1) | N7: Pavilion 1 | O7: Keynote Stage 1 (Pavilion 1)
A8: 7 | B8: Day 2 | C8: 0.39583333 | E8: Airport Keynote | F8: Interview | G8: CEO Interview: Thierry Ligonnière, CEO, ANA - Aeroportos de Portugal | H8: Thierry Ligonnière – Chief Executive Officer, ANA Aeroportos de Portugal Ben Thompson – Presenter, BBC | I8: Thierry Ligonnière, Ben Thompson | J8: ANA Aeroportos de Portugal, BBC | K8: 2 | M8: Keynote Stage 2 (Pavilion 2) | N8: Pavilion 2 | O8: Keynote Stage 2 (Pavilion 2)
A9: 8 | B9: Day 2 | C9: 0.40277778 | E9: Airport Keynote | F9: Interview | G9: CEO Interview: Pierre-Hugues Schmit, CEO, London Gatwick | H9: Pierre-Hugues Schmit – Chief Executive Officer, London Gatwick Airport Ben Thompson – Presenter, BBC | I9: Pierre-Hugues Schmit, Ben Thompson | J9: London Gatwick Airport, BBC | K9: 2 | M9: Keynote Stage 2 (Pavilion 2) | N9: Pavilion 2 | O9: Keynote Stage 2 (Pavilion 2)
A10: 9 | B10: Day 2 | C10: 0.40277778 | E10: Airline Keynote | F10: Interview | G10: CEO Interview: Roberto Alvo, CEO, LATAM | H10: Roberto Alvo – CEO, Latam Airlines Group Peter Campbell – Global Transport Correspondent, Financial Times | I10: Roberto Alvo, Peter Campbell | J10: Latam Airlines Group, Financial Times | K10: 2 | M10: Keynote Stage 1 (Pavilion 1) | N10: Pavilion 1 | O10: Keynote Stage 1 (Pavilion 1)
A11: 10 | B11: Day 2 | C11: 0.40972222 | E11: Airline Keynote | F11: Panel | G11: Keynote CEO Panel: Writing the next chapter of aviation history in an age of uncertainty | H11: Luís Rodrigues – Chief Executive Officer, Tap Air Portugal Adrian Neuhauser – Chief Executive Officer, Abra Group Roberto Alvo – CEO, Latam Airlines Group | I11: Luís Rodrigues, Adrian Neuhauser, Roberto Alvo | J11: Tap Air Portugal, Abra Group, Latam Airlines Group | K11: 3 | L11: 1 | M11: Keynote Stage 1 (Pavilion 1) | N11: Pavilion 1 | O11: Keynote Stage 1 (Pavilion 1) | P11: Investing in the right areas for growth: identifying true game changes from the trendy fad • Navigating geopolitical instability and preparing for unknowns to reduce the impact of disruption • Long Term Strategy planning by optimising operations and working with industry to solve supply chain constraint • Working as an industry to improve global challenges including sustainability, workforce challenges and safety
A12: 11 | B12: Day 2 | C12: 0.40972222 | E12: Airport Keynote | F12: Interview | G12: CEO Interview: Paul Griffiths, CEO, Dubai Airports | H12: Paul Griffiths – Chief Executive Officer, Dubai Airports Company Ben Thompson – Presenter, BBC | I12: Paul Griffiths, Ben Thompson | J12: Dubai Airports Company, BBC | K12: 2 | M12: Keynote Stage 2 (Pavilion 2) | N12: Pavilion 2 | O12: Keynote Stage 2 (Pavilion 2)
A13: 12 | B13: Day 2 | C13: 0.41666667 | E13: Airport Keynote | F13: Panel | G13: Keynote Panel: Growth without compromise – rethinking the airport model for sustainable growth | H13: Stefan Schulte – Chief Executive Officer, Fraport AG Warwick Brady – President & CEO, SWISSPORT Paul Griffiths – Chief Executive Officer, Dubai Airports Company | I13: Stefan Schulte, Warwick Brady, Paul Griffiths | J13: Fraport AG, SWISSPORT, Dubai Airports Company | K13: 3 | L13: 2 | M13: Keynote Stage 2 (Pavilion 2) | N13: Pavilion 2 | O13: Keynote Stage 2 (Pavilion 2) | P13: How can airports manage growth and capacity through both infrastructure development and smarter use of existing assets? • As traffic rises, how do we maintain operational resilience while protecting the passenger experience? • How can better coordination across airlines, airports and ground handlers reduce operational complexity? • As competition between hubs intensifies, how can airports differentiate through efficiency, technology and experience? • What investments in infrastructure, operations and digital capability will define the most competitive airports over the next 3-5 years?
A14: 13 | B14: Day 2 | C14: 0.44791667 | D14: 0.47916667 | E14: Roundtable | F14: Roundtable | G14: Table 01: FLYR Roundtable - Funding the move to Offer & Order: Creating the right time for the right move | H14: Rodrigo López Josh Crandall | I14: Rodrigo López, Josh Crandall | K14: 2 | M14: Roundtable Area (Pavilion 2) | N14: Pavilion 2 | O14: Roundtable area, Pavilion 2 | Q14: 36 | R14: 40 | S14: =R14-Q14 -> 4 | T14: Open
A15: 14 | B15: Day 2 | C15: 0.44791667 | D15: 0.47916667 | E15: Roundtable | F15: Roundtable | G15: Table 2: ATPCO Roundtable - Airline product catalogs: a foundation for retailing at scale | H15: Doug Sharpe Megan Humphries | I15: Doug Sharpe, Megan Humphries | K15: 2 | M15: Roundtable Area (Pavilion 2) | N15: Pavilion 2 | O15: Roundtable area, Pavilion 2 | Q15: 12 | R15: 40 | S15: =R15-Q15 -> 28 | T15: Open
A16: 15 | B16: Day 2 | C16: 0.44791667 | D16: 0.47916667 | E16: Roundtable | F16: Roundtable | G16: Table 3: 15Below - 10 years of deploying AI in aviation: what works, what doesn’t and what we’ve learned | H16: Ali Tredinnick Joe Bennett | I16: Ali Tredinnick, Joe Bennett | K16: 2 | M16: Roundtable Area (Pavilion 2) | N16: Pavilion 2 | O16: Roundtable area, Pavilion 2 | Q16: 50 | R16: 50 | S16: =R16-Q16 -> 0 | T16: Full
A17: 16 | B17: Day 2 | C17: 0.44791667 | D17: 0.47916667 | E17: Roundtable | F17: Roundtable | G17: Table 4: OneReg Roundtable - Continuous confidence: reimagining how aviation compliance works | H17: Billie Moore Angel Matsis | I17: Billie Moore, Angel Matsis | K17: 2 | M17: Roundtable Area (Pavilion 2) | N17: Pavilion 2 | O17: Roundtable area, Pavilion 2 | Q17: 7 | R17: 40 | S17: =R17-Q17 -> 33 | T17: Open
A18: 17 | B18: Day 2 | C18: 0.44791667 | D18: 0.47916667 | E18: Roundtable | F18: Roundtable | G18: Table 5: Seatboost Roundtable - The gate-side goldmine: Gamification, dynamic pricing, and monetizing the premium cabin | H18: Kevin Stamler | I18: Kevin Stamler | K18: 1 | M18: Roundtable Area (Pavilion 2) | N18: Pavilion 2 | O18: Roundtable area, Pavilion 2 | Q18: 18 | R18: 40 | S18: =R18-Q18 -> 22 | T18: Open
A19: 18 | B19: Day 2 | C19: 0.44791667 | D19: 0.47916667 | E19: Roundtable | F19: Roundtable | G19: Table 6: Ping Identity Roundtable - Whose agent is it anyway? | H19: Alexander Laurie Emanuela Maftieu | I19: Alexander Laurie, Emanuela Maftieu | K19: 2 | M19: Roundtable Area (Pavilion 2) | N19: Pavilion 2 | O19: Roundtable area, Pavilion 2 | Q19: 1 | R19: 40 | S19: =R19-Q19 -> 39 | T19: Open
A20: 19 | B20: Day 2 | C20: 0.44791667 | D20: 0.47916667 | E20: Roundtable | F20: Roundtable | G20: Table 7: ADA Roundtable - Agentic IROPs: Turning flight re-accom into your biggest loyalty moment | H20: Mike Murchison Tatiana Deabreu | I20: Mike Murchison, Tatiana Deabreu | K20: 2 | M20: Roundtable Area (Pavilion 2) | N20: Pavilion 2 | O20: Roundtable area, Pavilion 2 | Q20: 31 | R20: 40 | S20: =R20-Q20 -> 9 | T20: Open
A21: 20 | B21: Day 2 | C21: 0.44791667 | D21: 0.47916667 | E21: Roundtable | F21: Roundtable | G21: Table 8: Lufthansa Industry Solutions Roundtable - How airports, airlines and partners can create value through collaboration | H21: Karina Mehl Michael Kleinert | I21: Karina Mehl, Michael Kleinert | K21: 2 | M21: Roundtable Area (Pavilion 2) | N21: Pavilion 2 | O21: Roundtable area, Pavilion 2 | Q21: 40 | R21: 40 | S21: =R21-Q21 -> 0 | T21: Full
A22: 21 | B22: Day 2 | C22: 0.44791667 | D22: 0.47916667 | E22: Roundtable | F22: Roundtable | G22: Table 9: Chubb Roundtable - When delays happen, payouts shouldn't wait. Using parametrics to turn flight disruption into passenger loyalty. | H22: Ruben Rivero | I22: Ruben Rivero | K22: 1 | M22: Roundtable Area (Pavilion 2) | N22: Pavilion 2 | O22: Roundtable area, Pavilion 2 | Q22: 9 | R22: 40 | S22: =R22-Q22 -> 31 | T22: Open
A23: 22 | B23: Day 2 | C23: 0.44791667 | D23: 0.47916667 | E23: Roundtable | F23: Roundtable | G23: Table10: Intellicene Roundtable - The connected airport: Turning data into operational intelligence | H23: Matthew Maychrowitz Rebecca Rea | I23: Matthew Maychrowitz, Rebecca Rea | K23: 2 | M23: Roundtable Area (Pavilion 2) | N23: Pavilion 2 | O23: Roundtable area, Pavilion 2 | Q23: 26 | R23: 40 | S23: =R23-Q23 -> 14 | T23: Open
A24: 23 | B24: Day 2 | C24: 0.44791667 | D24: 0.47916667 | E24: Roundtable | F24: Roundtable | G24: Table11: Thoughtspot Roundtable - From Insight to Action: How aviation leaders are scaling agentic analytics | H24: James Davies Charlotte Ross | I24: James Davies, Charlotte Ross | K24: 2 | M24: Roundtable Area (Pavilion 2) | N24: Pavilion 2 | O24: Roundtable area, Pavilion 2 | Q24: 23 | R24: 40 | S24: =R24-Q24 -> 17 | T24: Open (you are registered)
A25: 24 | B25: Day 2 | C25: 0.44791667 | D25: 0.47916667 | E25: Roundtable | F25: Roundtable | G25: Table12: Volantio Roundtable - Beyond the AI hype: Can agents finally connect revenue, operations and customer experience? | H25: Ana Maria Escobar Azim Barodawala | I25: Ana Maria Escobar, Azim Barodawala | K25: 2 | M25: Roundtable Area (Pavilion 2) | N25: Pavilion 2 | O25: Roundtable area, Pavilion 2 | Q25: 13 | R25: 40 | S25: =R25-Q25 -> 27 | T25: Open
... A33: 32 | B33: Day 2 | C33: 0.44791667 | D33: 0.47916667 | E33: Roundtable | F33: Roundtable | G33: Table20: Zingly Roundtable - Case study: AI in production at Pegasus Airlines: Beyond deflection to completed passenger journeys | H33: Baris Findik Gaurav Passi | I33: Baris Findik, Gaurav Passi | K33: 2 | M33: Roundtable Area (Pavilion 2) | N33: Pavilion 2 | O33: Roundtable area, Pavilion 2 | Q33: 10 | R33: 40 | S33: =R33-Q33 -> 30 | T33: Open
A34: 33 | B34: Day 2 | C34: 0.47916667 | E34: Networking | F34: Networking | G34: Aviation Connect: Session 3 | H34: Host, World Aviation Festival | I34: Host | J34: World Aviation Festival | K34: 1 | M34: Aviation Connect Zone (Pavilion 2) | N34: Pavilion 2 | O34: Aviation Connect Zone Pavilion 2 | P34: Aviation Connect is our dedicated networking hour. Book 15 minute meetings via the Aviation Connect Platform and make the most of your time at WAF. No other sessions, workshops or activities are taking place during this time.
A35: 34 | B35: Day 2 | C35: 0.51736111 | E35: Loyalty | F35: Chair Remarks | G35: Chair opening remarks | H35: Harald Deprosse – Partner, Envolved GmbH | I35: Harald Deprosse | J35: Envolved GmbH | K35: 1 | M35: Track 3 (Pavilion 1) | N35: Pavilion 1 | O35: Track 3 (Pavilion 1)
A36: 35 | B36: Day 2 | C36: 0.52083333 | E36: Sustainability | F36: Fireside Chat | G36: Fireside Chat: Growth without compromise – can airlines decarbonise while remaining competitive? | H36: Maria Whittaker – Chief Corporate Responsibility Officer, Abra Group Patrick Edmond – Chief Commercial Officer, Future Energy Global | I36: Maria Whittaker, Patrick Edmond | J36: Abra Group, Future Energy Global | K36: 2 | M36: Track 10 (Pavilion 2) | N36: Pavilion 2 | O36: Track 10 (Pavilion 2)
A37: 36 | B37: Day 2 | C37: 0.52083333 | E37: Loyalty | F37: Welcome | G37: Plusgrade Welcome | H37: Richard Wolfman – SVP Global Business Development, Plusgrade | I37: Richard Wolfman | J37: Plusgrade | K37: 1 | M37: Track 3 (Pavilion 1) | N37: Pavilion 1 | O37: Track 3, Pav 1
